{
 "cells": [
  {
   "cell_type": "code",
   "execution_count": 14,
   "metadata": {},
   "outputs": [],
   "source": [
    "import pandas as pd\n",
    "import numpy as np\n",
    "from sklearn.linear_model import  LogisticRegression\n",
    "from sklearn.model_selection import GridSearchCV\n",
    "from sklearn.neighbors import KNeighborsClassifier\n",
    "from sklearn.model_selection import StratifiedKFold\n",
    "from sklearn.pipeline import Pipeline\n",
    "from sklearn.naive_bayes import GaussianNB\n",
    "from sklearn.preprocessing import StandardScaler, MinMaxScaler\n",
    "from sklearn.preprocessing import LabelEncoder\n",
    "from sklearn.model_selection import train_test_split\n",
    "from warnings import simplefilter\n",
    "from sklearn.exceptions import ConvergenceWarning\n",
    "simplefilter(\"ignore\", category=ConvergenceWarning)"
   ]
  },
  {
   "cell_type": "code",
   "execution_count": 15,
   "metadata": {},
   "outputs": [],
   "source": [
    "img = pd.read_csv('Vehicle.csv')\n",
    "#Label Encoding\n",
    "lbl = LabelEncoder()\n",
    "img['Class'] = lbl.fit_transform(img['Class'])\n",
    "\n",
    "X = img.drop('Class',axis=1)\n",
    "y = img['Class']\n",
    "X_train, X_test, y_train, y_test = train_test_split(X, y, test_size=0.3, random_state=23)"
   ]
  },
  {
   "cell_type": "markdown",
   "metadata": {},
   "source": [
    "Logistic Regression"
   ]
  },
  {
   "cell_type": "code",
   "execution_count": 16,
   "metadata": {},
   "outputs": [
    {
     "name": "stderr",
     "output_type": "stream",
     "text": [
      "/home/dai/anaconda3/lib/python3.11/site-packages/scipy/optimize/_linesearch.py:466: LineSearchWarning: The line search algorithm did not converge\n",
      "  warn('The line search algorithm did not converge', LineSearchWarning)\n",
      "/home/dai/anaconda3/lib/python3.11/site-packages/scipy/optimize/_linesearch.py:314: LineSearchWarning: The line search algorithm did not converge\n",
      "  warn('The line search algorithm did not converge', LineSearchWarning)\n",
      "/home/dai/anaconda3/lib/python3.11/site-packages/sklearn/utils/optimize.py:204: UserWarning: Line Search failed\n",
      "  warnings.warn(\"Line Search failed\")\n",
      "/home/dai/anaconda3/lib/python3.11/site-packages/scipy/optimize/_linesearch.py:466: LineSearchWarning: The line search algorithm did not converge\n",
      "  warn('The line search algorithm did not converge', LineSearchWarning)\n",
      "/home/dai/anaconda3/lib/python3.11/site-packages/scipy/optimize/_linesearch.py:314: LineSearchWarning: The line search algorithm did not converge\n",
      "  warn('The line search algorithm did not converge', LineSearchWarning)\n",
      "/home/dai/anaconda3/lib/python3.11/site-packages/scipy/optimize/_linesearch.py:466: LineSearchWarning: The line search algorithm did not converge\n",
      "  warn('The line search algorithm did not converge', LineSearchWarning)\n",
      "/home/dai/anaconda3/lib/python3.11/site-packages/scipy/optimize/_linesearch.py:314: LineSearchWarning: The line search algorithm did not converge\n",
      "  warn('The line search algorithm did not converge', LineSearchWarning)\n",
      "/home/dai/anaconda3/lib/python3.11/site-packages/scipy/optimize/_linesearch.py:314: LineSearchWarning: The line search algorithm did not converge\n",
      "  warn('The line search algorithm did not converge', LineSearchWarning)\n",
      "/home/dai/anaconda3/lib/python3.11/site-packages/sklearn/utils/optimize.py:204: UserWarning: Line Search failed\n",
      "  warnings.warn(\"Line Search failed\")\n",
      "/home/dai/anaconda3/lib/python3.11/site-packages/scipy/optimize/_linesearch.py:466: LineSearchWarning: The line search algorithm did not converge\n",
      "  warn('The line search algorithm did not converge', LineSearchWarning)\n",
      "/home/dai/anaconda3/lib/python3.11/site-packages/scipy/optimize/_linesearch.py:466: LineSearchWarning: The line search algorithm did not converge\n",
      "  warn('The line search algorithm did not converge', LineSearchWarning)\n",
      "/home/dai/anaconda3/lib/python3.11/site-packages/scipy/optimize/_linesearch.py:314: LineSearchWarning: The line search algorithm did not converge\n",
      "  warn('The line search algorithm did not converge', LineSearchWarning)\n",
      "/home/dai/anaconda3/lib/python3.11/site-packages/scipy/optimize/_linesearch.py:466: LineSearchWarning: The line search algorithm did not converge\n",
      "  warn('The line search algorithm did not converge', LineSearchWarning)\n",
      "/home/dai/anaconda3/lib/python3.11/site-packages/scipy/optimize/_linesearch.py:314: LineSearchWarning: The line search algorithm did not converge\n",
      "  warn('The line search algorithm did not converge', LineSearchWarning)\n",
      "/home/dai/anaconda3/lib/python3.11/site-packages/scipy/optimize/_linesearch.py:466: LineSearchWarning: The line search algorithm did not converge\n",
      "  warn('The line search algorithm did not converge', LineSearchWarning)\n",
      "/home/dai/anaconda3/lib/python3.11/site-packages/scipy/optimize/_linesearch.py:314: LineSearchWarning: The line search algorithm did not converge\n",
      "  warn('The line search algorithm did not converge', LineSearchWarning)\n",
      "/home/dai/anaconda3/lib/python3.11/site-packages/scipy/optimize/_linesearch.py:466: LineSearchWarning: The line search algorithm did not converge\n",
      "  warn('The line search algorithm did not converge', LineSearchWarning)\n",
      "/home/dai/anaconda3/lib/python3.11/site-packages/scipy/optimize/_linesearch.py:314: LineSearchWarning: The line search algorithm did not converge\n",
      "  warn('The line search algorithm did not converge', LineSearchWarning)\n",
      "/home/dai/anaconda3/lib/python3.11/site-packages/scipy/optimize/_linesearch.py:466: LineSearchWarning: The line search algorithm did not converge\n",
      "  warn('The line search algorithm did not converge', LineSearchWarning)\n",
      "/home/dai/anaconda3/lib/python3.11/site-packages/scipy/optimize/_linesearch.py:314: LineSearchWarning: The line search algorithm did not converge\n",
      "  warn('The line search algorithm did not converge', LineSearchWarning)\n",
      "/home/dai/anaconda3/lib/python3.11/site-packages/scipy/optimize/_linesearch.py:425: LineSearchWarning: Rounding errors prevent the line search from converging\n",
      "  warn(msg, LineSearchWarning)\n",
      "/home/dai/anaconda3/lib/python3.11/site-packages/sklearn/utils/optimize.py:204: UserWarning: Line Search failed\n",
      "  warnings.warn(\"Line Search failed\")\n",
      "/home/dai/anaconda3/lib/python3.11/site-packages/sklearn/model_selection/_validation.py:425: FitFailedWarning: \n",
      "130 fits failed out of a total of 240.\n",
      "The score on these train-test partitions for these parameters will be set to nan.\n",
      "If these failures are not expected, you can try to debug them by setting error_score='raise'.\n",
      "\n",
      "Below are more details about the failures:\n",
      "--------------------------------------------------------------------------------\n",
      "10 fits failed with the following error:\n",
      "Traceback (most recent call last):\n",
      "  File \"/home/dai/anaconda3/lib/python3.11/site-packages/sklearn/model_selection/_validation.py\", line 729, in _fit_and_score\n",
      "    estimator.fit(X_train, y_train, **fit_params)\n",
      "  File \"/home/dai/anaconda3/lib/python3.11/site-packages/sklearn/base.py\", line 1152, in wrapper\n",
      "    return fit_method(estimator, *args, **kwargs)\n",
      "           ^^^^^^^^^^^^^^^^^^^^^^^^^^^^^^^^^^^^^^\n",
      "  File \"/home/dai/anaconda3/lib/python3.11/site-packages/sklearn/linear_model/_logistic.py\", line 1169, in fit\n",
      "    solver = _check_solver(self.solver, self.penalty, self.dual)\n",
      "             ^^^^^^^^^^^^^^^^^^^^^^^^^^^^^^^^^^^^^^^^^^^^^^^^^^^\n",
      "  File \"/home/dai/anaconda3/lib/python3.11/site-packages/sklearn/linear_model/_logistic.py\", line 56, in _check_solver\n",
      "    raise ValueError(\n",
      "ValueError: Solver lbfgs supports only 'l2' or 'none' penalties, got l1 penalty.\n",
      "\n",
      "--------------------------------------------------------------------------------\n",
      "10 fits failed with the following error:\n",
      "Traceback (most recent call last):\n",
      "  File \"/home/dai/anaconda3/lib/python3.11/site-packages/sklearn/model_selection/_validation.py\", line 729, in _fit_and_score\n",
      "    estimator.fit(X_train, y_train, **fit_params)\n",
      "  File \"/home/dai/anaconda3/lib/python3.11/site-packages/sklearn/base.py\", line 1152, in wrapper\n",
      "    return fit_method(estimator, *args, **kwargs)\n",
      "           ^^^^^^^^^^^^^^^^^^^^^^^^^^^^^^^^^^^^^^\n",
      "  File \"/home/dai/anaconda3/lib/python3.11/site-packages/sklearn/linear_model/_logistic.py\", line 1169, in fit\n",
      "    solver = _check_solver(self.solver, self.penalty, self.dual)\n",
      "             ^^^^^^^^^^^^^^^^^^^^^^^^^^^^^^^^^^^^^^^^^^^^^^^^^^^\n",
      "  File \"/home/dai/anaconda3/lib/python3.11/site-packages/sklearn/linear_model/_logistic.py\", line 56, in _check_solver\n",
      "    raise ValueError(\n",
      "ValueError: Solver newton-cg supports only 'l2' or 'none' penalties, got l1 penalty.\n",
      "\n",
      "--------------------------------------------------------------------------------\n",
      "10 fits failed with the following error:\n",
      "Traceback (most recent call last):\n",
      "  File \"/home/dai/anaconda3/lib/python3.11/site-packages/sklearn/model_selection/_validation.py\", line 729, in _fit_and_score\n",
      "    estimator.fit(X_train, y_train, **fit_params)\n",
      "  File \"/home/dai/anaconda3/lib/python3.11/site-packages/sklearn/base.py\", line 1152, in wrapper\n",
      "    return fit_method(estimator, *args, **kwargs)\n",
      "           ^^^^^^^^^^^^^^^^^^^^^^^^^^^^^^^^^^^^^^\n",
      "  File \"/home/dai/anaconda3/lib/python3.11/site-packages/sklearn/linear_model/_logistic.py\", line 1169, in fit\n",
      "    solver = _check_solver(self.solver, self.penalty, self.dual)\n",
      "             ^^^^^^^^^^^^^^^^^^^^^^^^^^^^^^^^^^^^^^^^^^^^^^^^^^^\n",
      "  File \"/home/dai/anaconda3/lib/python3.11/site-packages/sklearn/linear_model/_logistic.py\", line 56, in _check_solver\n",
      "    raise ValueError(\n",
      "ValueError: Solver newton-cholesky supports only 'l2' or 'none' penalties, got l1 penalty.\n",
      "\n",
      "--------------------------------------------------------------------------------\n",
      "10 fits failed with the following error:\n",
      "Traceback (most recent call last):\n",
      "  File \"/home/dai/anaconda3/lib/python3.11/site-packages/sklearn/model_selection/_validation.py\", line 729, in _fit_and_score\n",
      "    estimator.fit(X_train, y_train, **fit_params)\n",
      "  File \"/home/dai/anaconda3/lib/python3.11/site-packages/sklearn/base.py\", line 1152, in wrapper\n",
      "    return fit_method(estimator, *args, **kwargs)\n",
      "           ^^^^^^^^^^^^^^^^^^^^^^^^^^^^^^^^^^^^^^\n",
      "  File \"/home/dai/anaconda3/lib/python3.11/site-packages/sklearn/linear_model/_logistic.py\", line 1169, in fit\n",
      "    solver = _check_solver(self.solver, self.penalty, self.dual)\n",
      "             ^^^^^^^^^^^^^^^^^^^^^^^^^^^^^^^^^^^^^^^^^^^^^^^^^^^\n",
      "  File \"/home/dai/anaconda3/lib/python3.11/site-packages/sklearn/linear_model/_logistic.py\", line 56, in _check_solver\n",
      "    raise ValueError(\n",
      "ValueError: Solver sag supports only 'l2' or 'none' penalties, got l1 penalty.\n",
      "\n",
      "--------------------------------------------------------------------------------\n",
      "10 fits failed with the following error:\n",
      "Traceback (most recent call last):\n",
      "  File \"/home/dai/anaconda3/lib/python3.11/site-packages/sklearn/model_selection/_validation.py\", line 729, in _fit_and_score\n",
      "    estimator.fit(X_train, y_train, **fit_params)\n",
      "  File \"/home/dai/anaconda3/lib/python3.11/site-packages/sklearn/base.py\", line 1152, in wrapper\n",
      "    return fit_method(estimator, *args, **kwargs)\n",
      "           ^^^^^^^^^^^^^^^^^^^^^^^^^^^^^^^^^^^^^^\n",
      "  File \"/home/dai/anaconda3/lib/python3.11/site-packages/sklearn/linear_model/_logistic.py\", line 1169, in fit\n",
      "    solver = _check_solver(self.solver, self.penalty, self.dual)\n",
      "             ^^^^^^^^^^^^^^^^^^^^^^^^^^^^^^^^^^^^^^^^^^^^^^^^^^^\n",
      "  File \"/home/dai/anaconda3/lib/python3.11/site-packages/sklearn/linear_model/_logistic.py\", line 56, in _check_solver\n",
      "    raise ValueError(\n",
      "ValueError: Solver lbfgs supports only 'l2' or 'none' penalties, got elasticnet penalty.\n",
      "\n",
      "--------------------------------------------------------------------------------\n",
      "10 fits failed with the following error:\n",
      "Traceback (most recent call last):\n",
      "  File \"/home/dai/anaconda3/lib/python3.11/site-packages/sklearn/model_selection/_validation.py\", line 729, in _fit_and_score\n",
      "    estimator.fit(X_train, y_train, **fit_params)\n",
      "  File \"/home/dai/anaconda3/lib/python3.11/site-packages/sklearn/base.py\", line 1152, in wrapper\n",
      "    return fit_method(estimator, *args, **kwargs)\n",
      "           ^^^^^^^^^^^^^^^^^^^^^^^^^^^^^^^^^^^^^^\n",
      "  File \"/home/dai/anaconda3/lib/python3.11/site-packages/sklearn/linear_model/_logistic.py\", line 1169, in fit\n",
      "    solver = _check_solver(self.solver, self.penalty, self.dual)\n",
      "             ^^^^^^^^^^^^^^^^^^^^^^^^^^^^^^^^^^^^^^^^^^^^^^^^^^^\n",
      "  File \"/home/dai/anaconda3/lib/python3.11/site-packages/sklearn/linear_model/_logistic.py\", line 66, in _check_solver\n",
      "    raise ValueError(\n",
      "ValueError: Only 'saga' solver supports elasticnet penalty, got solver=liblinear.\n",
      "\n",
      "--------------------------------------------------------------------------------\n",
      "10 fits failed with the following error:\n",
      "Traceback (most recent call last):\n",
      "  File \"/home/dai/anaconda3/lib/python3.11/site-packages/sklearn/model_selection/_validation.py\", line 729, in _fit_and_score\n",
      "    estimator.fit(X_train, y_train, **fit_params)\n",
      "  File \"/home/dai/anaconda3/lib/python3.11/site-packages/sklearn/base.py\", line 1152, in wrapper\n",
      "    return fit_method(estimator, *args, **kwargs)\n",
      "           ^^^^^^^^^^^^^^^^^^^^^^^^^^^^^^^^^^^^^^\n",
      "  File \"/home/dai/anaconda3/lib/python3.11/site-packages/sklearn/linear_model/_logistic.py\", line 1169, in fit\n",
      "    solver = _check_solver(self.solver, self.penalty, self.dual)\n",
      "             ^^^^^^^^^^^^^^^^^^^^^^^^^^^^^^^^^^^^^^^^^^^^^^^^^^^\n",
      "  File \"/home/dai/anaconda3/lib/python3.11/site-packages/sklearn/linear_model/_logistic.py\", line 56, in _check_solver\n",
      "    raise ValueError(\n",
      "ValueError: Solver newton-cg supports only 'l2' or 'none' penalties, got elasticnet penalty.\n",
      "\n",
      "--------------------------------------------------------------------------------\n",
      "10 fits failed with the following error:\n",
      "Traceback (most recent call last):\n",
      "  File \"/home/dai/anaconda3/lib/python3.11/site-packages/sklearn/model_selection/_validation.py\", line 729, in _fit_and_score\n",
      "    estimator.fit(X_train, y_train, **fit_params)\n",
      "  File \"/home/dai/anaconda3/lib/python3.11/site-packages/sklearn/base.py\", line 1152, in wrapper\n",
      "    return fit_method(estimator, *args, **kwargs)\n",
      "           ^^^^^^^^^^^^^^^^^^^^^^^^^^^^^^^^^^^^^^\n",
      "  File \"/home/dai/anaconda3/lib/python3.11/site-packages/sklearn/linear_model/_logistic.py\", line 1169, in fit\n",
      "    solver = _check_solver(self.solver, self.penalty, self.dual)\n",
      "             ^^^^^^^^^^^^^^^^^^^^^^^^^^^^^^^^^^^^^^^^^^^^^^^^^^^\n",
      "  File \"/home/dai/anaconda3/lib/python3.11/site-packages/sklearn/linear_model/_logistic.py\", line 56, in _check_solver\n",
      "    raise ValueError(\n",
      "ValueError: Solver newton-cholesky supports only 'l2' or 'none' penalties, got elasticnet penalty.\n",
      "\n",
      "--------------------------------------------------------------------------------\n",
      "10 fits failed with the following error:\n",
      "Traceback (most recent call last):\n",
      "  File \"/home/dai/anaconda3/lib/python3.11/site-packages/sklearn/model_selection/_validation.py\", line 729, in _fit_and_score\n",
      "    estimator.fit(X_train, y_train, **fit_params)\n",
      "  File \"/home/dai/anaconda3/lib/python3.11/site-packages/sklearn/base.py\", line 1152, in wrapper\n",
      "    return fit_method(estimator, *args, **kwargs)\n",
      "           ^^^^^^^^^^^^^^^^^^^^^^^^^^^^^^^^^^^^^^\n",
      "  File \"/home/dai/anaconda3/lib/python3.11/site-packages/sklearn/linear_model/_logistic.py\", line 1169, in fit\n",
      "    solver = _check_solver(self.solver, self.penalty, self.dual)\n",
      "             ^^^^^^^^^^^^^^^^^^^^^^^^^^^^^^^^^^^^^^^^^^^^^^^^^^^\n",
      "  File \"/home/dai/anaconda3/lib/python3.11/site-packages/sklearn/linear_model/_logistic.py\", line 56, in _check_solver\n",
      "    raise ValueError(\n",
      "ValueError: Solver sag supports only 'l2' or 'none' penalties, got elasticnet penalty.\n",
      "\n",
      "--------------------------------------------------------------------------------\n",
      "10 fits failed with the following error:\n",
      "Traceback (most recent call last):\n",
      "  File \"/home/dai/anaconda3/lib/python3.11/site-packages/sklearn/model_selection/_validation.py\", line 729, in _fit_and_score\n",
      "    estimator.fit(X_train, y_train, **fit_params)\n",
      "  File \"/home/dai/anaconda3/lib/python3.11/site-packages/sklearn/base.py\", line 1152, in wrapper\n",
      "    return fit_method(estimator, *args, **kwargs)\n",
      "           ^^^^^^^^^^^^^^^^^^^^^^^^^^^^^^^^^^^^^^\n",
      "  File \"/home/dai/anaconda3/lib/python3.11/site-packages/sklearn/linear_model/_logistic.py\", line 1179, in fit\n",
      "    raise ValueError(\"l1_ratio must be specified when penalty is elasticnet.\")\n",
      "ValueError: l1_ratio must be specified when penalty is elasticnet.\n",
      "\n",
      "--------------------------------------------------------------------------------\n",
      "5 fits failed with the following error:\n",
      "Traceback (most recent call last):\n",
      "  File \"/home/dai/anaconda3/lib/python3.11/site-packages/sklearn/model_selection/_validation.py\", line 729, in _fit_and_score\n",
      "    estimator.fit(X_train, y_train, **fit_params)\n",
      "  File \"/home/dai/anaconda3/lib/python3.11/site-packages/sklearn/base.py\", line 1152, in wrapper\n",
      "    return fit_method(estimator, *args, **kwargs)\n",
      "           ^^^^^^^^^^^^^^^^^^^^^^^^^^^^^^^^^^^^^^\n",
      "  File \"/home/dai/anaconda3/lib/python3.11/site-packages/sklearn/linear_model/_logistic.py\", line 1228, in fit\n",
      "    self.coef_, self.intercept_, self.n_iter_ = _fit_liblinear(\n",
      "                                                ^^^^^^^^^^^^^^^\n",
      "  File \"/home/dai/anaconda3/lib/python3.11/site-packages/sklearn/svm/_base.py\", line 1229, in _fit_liblinear\n",
      "    solver_type = _get_liblinear_solver_type(multi_class, penalty, loss, dual)\n",
      "                  ^^^^^^^^^^^^^^^^^^^^^^^^^^^^^^^^^^^^^^^^^^^^^^^^^^^^^^^^^^^^\n",
      "  File \"/home/dai/anaconda3/lib/python3.11/site-packages/sklearn/svm/_base.py\", line 1060, in _get_liblinear_solver_type\n",
      "    raise ValueError(\n",
      "ValueError: Unsupported set of arguments: The combination of penalty='None' and loss='logistic_regression' is not supported, Parameters: penalty=None, loss='logistic_regression', dual=False\n",
      "\n",
      "--------------------------------------------------------------------------------\n",
      "15 fits failed with the following error:\n",
      "Traceback (most recent call last):\n",
      "  File \"/home/dai/anaconda3/lib/python3.11/site-packages/sklearn/model_selection/_validation.py\", line 729, in _fit_and_score\n",
      "    estimator.fit(X_train, y_train, **fit_params)\n",
      "  File \"/home/dai/anaconda3/lib/python3.11/site-packages/sklearn/base.py\", line 1152, in wrapper\n",
      "    return fit_method(estimator, *args, **kwargs)\n",
      "           ^^^^^^^^^^^^^^^^^^^^^^^^^^^^^^^^^^^^^^\n",
      "  File \"/home/dai/anaconda3/lib/python3.11/site-packages/sklearn/linear_model/_logistic.py\", line 1219, in fit\n",
      "    multi_class = _check_multi_class(self.multi_class, solver, len(self.classes_))\n",
      "                  ^^^^^^^^^^^^^^^^^^^^^^^^^^^^^^^^^^^^^^^^^^^^^^^^^^^^^^^^^^^^^^^^\n",
      "  File \"/home/dai/anaconda3/lib/python3.11/site-packages/sklearn/linear_model/_logistic.py\", line 92, in _check_multi_class\n",
      "    raise ValueError(\"Solver %s does not support a multinomial backend.\" % solver)\n",
      "ValueError: Solver liblinear does not support a multinomial backend.\n",
      "\n",
      "--------------------------------------------------------------------------------\n",
      "10 fits failed with the following error:\n",
      "Traceback (most recent call last):\n",
      "  File \"/home/dai/anaconda3/lib/python3.11/site-packages/sklearn/model_selection/_validation.py\", line 729, in _fit_and_score\n",
      "    estimator.fit(X_train, y_train, **fit_params)\n",
      "  File \"/home/dai/anaconda3/lib/python3.11/site-packages/sklearn/base.py\", line 1152, in wrapper\n",
      "    return fit_method(estimator, *args, **kwargs)\n",
      "           ^^^^^^^^^^^^^^^^^^^^^^^^^^^^^^^^^^^^^^\n",
      "  File \"/home/dai/anaconda3/lib/python3.11/site-packages/sklearn/linear_model/_logistic.py\", line 1219, in fit\n",
      "    multi_class = _check_multi_class(self.multi_class, solver, len(self.classes_))\n",
      "                  ^^^^^^^^^^^^^^^^^^^^^^^^^^^^^^^^^^^^^^^^^^^^^^^^^^^^^^^^^^^^^^^^\n",
      "  File \"/home/dai/anaconda3/lib/python3.11/site-packages/sklearn/linear_model/_logistic.py\", line 92, in _check_multi_class\n",
      "    raise ValueError(\"Solver %s does not support a multinomial backend.\" % solver)\n",
      "ValueError: Solver newton-cholesky does not support a multinomial backend.\n",
      "\n",
      "  warnings.warn(some_fits_failed_message, FitFailedWarning)\n",
      "/home/dai/anaconda3/lib/python3.11/site-packages/sklearn/model_selection/_search.py:979: UserWarning: One or more of the test scores are non-finite: [        nan -0.48137936         nan         nan         nan -0.91415983\n",
      " -0.53371689 -0.46883207 -0.46772961 -0.46772998 -0.83365651 -0.91367235\n",
      "         nan         nan         nan         nan         nan         nan\n",
      " -0.52890592         nan -0.47564737 -0.47569147 -0.83352878 -0.91355879\n",
      "         nan         nan         nan         nan         nan -0.85270753\n",
      " -0.67953038         nan -0.43019987         nan -0.7700881  -0.85209438\n",
      "         nan         nan         nan         nan         nan         nan\n",
      " -0.67626528         nan -0.51694288         nan -0.77010407 -0.85206589]\n",
      "  warnings.warn(\n"
     ]
    },
    {
     "name": "stdout",
     "output_type": "stream",
     "text": [
      "{'multi_class': 'multinomial', 'penalty': 'l2', 'solver': 'newton-cg'}\n",
      "-0.43019987069217275\n"
     ]
    }
   ],
   "source": [
    "kfold = StratifiedKFold(n_splits=5, shuffle=True, random_state=23)\n",
    "lr = LogisticRegression()\n",
    "\n",
    "penalty = ['l1','l2','elasticnet',None]\n",
    "solver = ['lbfgs', 'liblinear', 'newton-cg', 'newton-cholesky', 'sag', 'saga']\n",
    "\n",
    "params = {'penalty':penalty,'solver':solver, 'multi_class':['ovr','multinomial']}\n",
    "gcv = GridSearchCV(lr,param_grid=params,cv=kfold, scoring='neg_log_loss')\n",
    "gcv.fit(X,y)\n",
    "print(gcv.best_params_)\n",
    "print(gcv.best_score_)"
   ]
  },
  {
   "cell_type": "markdown",
   "metadata": {},
   "source": [
    "KNN Classifier"
   ]
  },
  {
   "cell_type": "code",
   "execution_count": 17,
   "metadata": {},
   "outputs": [
    {
     "name": "stdout",
     "output_type": "stream",
     "text": [
      "{'KNN__n_neighbors': 16, 'SCL': StandardScaler()}\n",
      "-0.7943345007885417\n"
     ]
    }
   ],
   "source": [
    "kfold=StratifiedKFold(n_splits=5, shuffle=True, random_state=23)\n",
    "knn = KNeighborsClassifier()\n",
    "n_neighbors = np.arange(1,21)\n",
    "scaler = StandardScaler()\n",
    "pipe = Pipeline([('SCL',scaler),('KNN',knn)])\n",
    "params = {'KNN__n_neighbors':n_neighbors,'SCL':[StandardScaler(),MinMaxScaler()]}\n",
    "gcv = GridSearchCV(pipe,param_grid=params,cv=kfold,scoring='neg_log_loss')\n",
    "gcv.fit(X,y)\n",
    "print(gcv.best_params_)\n",
    "print(gcv.best_score_)"
   ]
  },
  {
   "cell_type": "markdown",
   "metadata": {},
   "source": [
    "Gaussian NB"
   ]
  },
  {
   "cell_type": "code",
   "execution_count": 18,
   "metadata": {},
   "outputs": [
    {
     "name": "stderr",
     "output_type": "stream",
     "text": [
      "/home/dai/anaconda3/lib/python3.11/site-packages/sklearn/metrics/_classification.py:2922: UserWarning: The y_pred values do not sum to one. Starting from 1.5 thiswill result in an error.\n",
      "  warnings.warn(\n",
      "/home/dai/anaconda3/lib/python3.11/site-packages/sklearn/metrics/_classification.py:2922: UserWarning: The y_pred values do not sum to one. Starting from 1.5 thiswill result in an error.\n",
      "  warnings.warn(\n",
      "/home/dai/anaconda3/lib/python3.11/site-packages/sklearn/metrics/_classification.py:2922: UserWarning: The y_pred values do not sum to one. Starting from 1.5 thiswill result in an error.\n",
      "  warnings.warn(\n",
      "/home/dai/anaconda3/lib/python3.11/site-packages/sklearn/metrics/_classification.py:2922: UserWarning: The y_pred values do not sum to one. Starting from 1.5 thiswill result in an error.\n",
      "  warnings.warn(\n",
      "/home/dai/anaconda3/lib/python3.11/site-packages/sklearn/metrics/_classification.py:2922: UserWarning: The y_pred values do not sum to one. Starting from 1.5 thiswill result in an error.\n",
      "  warnings.warn(\n",
      "/home/dai/anaconda3/lib/python3.11/site-packages/sklearn/metrics/_classification.py:2922: UserWarning: The y_pred values do not sum to one. Starting from 1.5 thiswill result in an error.\n",
      "  warnings.warn(\n",
      "/home/dai/anaconda3/lib/python3.11/site-packages/sklearn/metrics/_classification.py:2922: UserWarning: The y_pred values do not sum to one. Starting from 1.5 thiswill result in an error.\n",
      "  warnings.warn(\n",
      "/home/dai/anaconda3/lib/python3.11/site-packages/sklearn/metrics/_classification.py:2922: UserWarning: The y_pred values do not sum to one. Starting from 1.5 thiswill result in an error.\n",
      "  warnings.warn(\n",
      "/home/dai/anaconda3/lib/python3.11/site-packages/sklearn/metrics/_classification.py:2922: UserWarning: The y_pred values do not sum to one. Starting from 1.5 thiswill result in an error.\n",
      "  warnings.warn(\n",
      "/home/dai/anaconda3/lib/python3.11/site-packages/sklearn/metrics/_classification.py:2922: UserWarning: The y_pred values do not sum to one. Starting from 1.5 thiswill result in an error.\n",
      "  warnings.warn(\n",
      "/home/dai/anaconda3/lib/python3.11/site-packages/sklearn/metrics/_classification.py:2922: UserWarning: The y_pred values do not sum to one. Starting from 1.5 thiswill result in an error.\n",
      "  warnings.warn(\n",
      "/home/dai/anaconda3/lib/python3.11/site-packages/sklearn/metrics/_classification.py:2922: UserWarning: The y_pred values do not sum to one. Starting from 1.5 thiswill result in an error.\n",
      "  warnings.warn(\n",
      "/home/dai/anaconda3/lib/python3.11/site-packages/sklearn/metrics/_classification.py:2922: UserWarning: The y_pred values do not sum to one. Starting from 1.5 thiswill result in an error.\n",
      "  warnings.warn(\n",
      "/home/dai/anaconda3/lib/python3.11/site-packages/sklearn/metrics/_classification.py:2922: UserWarning: The y_pred values do not sum to one. Starting from 1.5 thiswill result in an error.\n",
      "  warnings.warn(\n",
      "/home/dai/anaconda3/lib/python3.11/site-packages/sklearn/metrics/_classification.py:2922: UserWarning: The y_pred values do not sum to one. Starting from 1.5 thiswill result in an error.\n",
      "  warnings.warn(\n",
      "/home/dai/anaconda3/lib/python3.11/site-packages/sklearn/metrics/_classification.py:2922: UserWarning: The y_pred values do not sum to one. Starting from 1.5 thiswill result in an error.\n",
      "  warnings.warn(\n",
      "/home/dai/anaconda3/lib/python3.11/site-packages/sklearn/metrics/_classification.py:2922: UserWarning: The y_pred values do not sum to one. Starting from 1.5 thiswill result in an error.\n",
      "  warnings.warn(\n",
      "/home/dai/anaconda3/lib/python3.11/site-packages/sklearn/metrics/_classification.py:2922: UserWarning: The y_pred values do not sum to one. Starting from 1.5 thiswill result in an error.\n",
      "  warnings.warn(\n",
      "/home/dai/anaconda3/lib/python3.11/site-packages/sklearn/metrics/_classification.py:2922: UserWarning: The y_pred values do not sum to one. Starting from 1.5 thiswill result in an error.\n",
      "  warnings.warn(\n",
      "/home/dai/anaconda3/lib/python3.11/site-packages/sklearn/metrics/_classification.py:2922: UserWarning: The y_pred values do not sum to one. Starting from 1.5 thiswill result in an error.\n",
      "  warnings.warn(\n",
      "/home/dai/anaconda3/lib/python3.11/site-packages/sklearn/metrics/_classification.py:2922: UserWarning: The y_pred values do not sum to one. Starting from 1.5 thiswill result in an error.\n",
      "  warnings.warn(\n",
      "/home/dai/anaconda3/lib/python3.11/site-packages/sklearn/metrics/_classification.py:2922: UserWarning: The y_pred values do not sum to one. Starting from 1.5 thiswill result in an error.\n",
      "  warnings.warn(\n",
      "/home/dai/anaconda3/lib/python3.11/site-packages/sklearn/metrics/_classification.py:2922: UserWarning: The y_pred values do not sum to one. Starting from 1.5 thiswill result in an error.\n",
      "  warnings.warn(\n",
      "/home/dai/anaconda3/lib/python3.11/site-packages/sklearn/metrics/_classification.py:2922: UserWarning: The y_pred values do not sum to one. Starting from 1.5 thiswill result in an error.\n",
      "  warnings.warn(\n",
      "/home/dai/anaconda3/lib/python3.11/site-packages/sklearn/metrics/_classification.py:2922: UserWarning: The y_pred values do not sum to one. Starting from 1.5 thiswill result in an error.\n",
      "  warnings.warn(\n",
      "/home/dai/anaconda3/lib/python3.11/site-packages/sklearn/metrics/_classification.py:2922: UserWarning: The y_pred values do not sum to one. Starting from 1.5 thiswill result in an error.\n",
      "  warnings.warn(\n",
      "/home/dai/anaconda3/lib/python3.11/site-packages/sklearn/metrics/_classification.py:2922: UserWarning: The y_pred values do not sum to one. Starting from 1.5 thiswill result in an error.\n",
      "  warnings.warn(\n",
      "/home/dai/anaconda3/lib/python3.11/site-packages/sklearn/metrics/_classification.py:2922: UserWarning: The y_pred values do not sum to one. Starting from 1.5 thiswill result in an error.\n",
      "  warnings.warn(\n",
      "/home/dai/anaconda3/lib/python3.11/site-packages/sklearn/metrics/_classification.py:2922: UserWarning: The y_pred values do not sum to one. Starting from 1.5 thiswill result in an error.\n",
      "  warnings.warn(\n",
      "/home/dai/anaconda3/lib/python3.11/site-packages/sklearn/metrics/_classification.py:2922: UserWarning: The y_pred values do not sum to one. Starting from 1.5 thiswill result in an error.\n",
      "  warnings.warn(\n",
      "/home/dai/anaconda3/lib/python3.11/site-packages/sklearn/metrics/_classification.py:2922: UserWarning: The y_pred values do not sum to one. Starting from 1.5 thiswill result in an error.\n",
      "  warnings.warn(\n",
      "/home/dai/anaconda3/lib/python3.11/site-packages/sklearn/metrics/_classification.py:2922: UserWarning: The y_pred values do not sum to one. Starting from 1.5 thiswill result in an error.\n",
      "  warnings.warn(\n",
      "/home/dai/anaconda3/lib/python3.11/site-packages/sklearn/metrics/_classification.py:2922: UserWarning: The y_pred values do not sum to one. Starting from 1.5 thiswill result in an error.\n",
      "  warnings.warn(\n",
      "/home/dai/anaconda3/lib/python3.11/site-packages/sklearn/metrics/_classification.py:2922: UserWarning: The y_pred values do not sum to one. Starting from 1.5 thiswill result in an error.\n",
      "  warnings.warn(\n",
      "/home/dai/anaconda3/lib/python3.11/site-packages/sklearn/metrics/_classification.py:2922: UserWarning: The y_pred values do not sum to one. Starting from 1.5 thiswill result in an error.\n",
      "  warnings.warn(\n",
      "/home/dai/anaconda3/lib/python3.11/site-packages/sklearn/metrics/_classification.py:2922: UserWarning: The y_pred values do not sum to one. Starting from 1.5 thiswill result in an error.\n",
      "  warnings.warn(\n",
      "/home/dai/anaconda3/lib/python3.11/site-packages/sklearn/metrics/_classification.py:2922: UserWarning: The y_pred values do not sum to one. Starting from 1.5 thiswill result in an error.\n",
      "  warnings.warn(\n",
      "/home/dai/anaconda3/lib/python3.11/site-packages/sklearn/metrics/_classification.py:2922: UserWarning: The y_pred values do not sum to one. Starting from 1.5 thiswill result in an error.\n",
      "  warnings.warn(\n",
      "/home/dai/anaconda3/lib/python3.11/site-packages/sklearn/metrics/_classification.py:2922: UserWarning: The y_pred values do not sum to one. Starting from 1.5 thiswill result in an error.\n",
      "  warnings.warn(\n",
      "/home/dai/anaconda3/lib/python3.11/site-packages/sklearn/metrics/_classification.py:2922: UserWarning: The y_pred values do not sum to one. Starting from 1.5 thiswill result in an error.\n",
      "  warnings.warn(\n",
      "/home/dai/anaconda3/lib/python3.11/site-packages/sklearn/metrics/_classification.py:2922: UserWarning: The y_pred values do not sum to one. Starting from 1.5 thiswill result in an error.\n",
      "  warnings.warn(\n",
      "/home/dai/anaconda3/lib/python3.11/site-packages/sklearn/metrics/_classification.py:2922: UserWarning: The y_pred values do not sum to one. Starting from 1.5 thiswill result in an error.\n",
      "  warnings.warn(\n",
      "/home/dai/anaconda3/lib/python3.11/site-packages/sklearn/metrics/_classification.py:2922: UserWarning: The y_pred values do not sum to one. Starting from 1.5 thiswill result in an error.\n",
      "  warnings.warn(\n",
      "/home/dai/anaconda3/lib/python3.11/site-packages/sklearn/metrics/_classification.py:2922: UserWarning: The y_pred values do not sum to one. Starting from 1.5 thiswill result in an error.\n",
      "  warnings.warn(\n",
      "/home/dai/anaconda3/lib/python3.11/site-packages/sklearn/metrics/_classification.py:2922: UserWarning: The y_pred values do not sum to one. Starting from 1.5 thiswill result in an error.\n",
      "  warnings.warn(\n",
      "/home/dai/anaconda3/lib/python3.11/site-packages/sklearn/metrics/_classification.py:2922: UserWarning: The y_pred values do not sum to one. Starting from 1.5 thiswill result in an error.\n",
      "  warnings.warn(\n",
      "/home/dai/anaconda3/lib/python3.11/site-packages/sklearn/metrics/_classification.py:2922: UserWarning: The y_pred values do not sum to one. Starting from 1.5 thiswill result in an error.\n",
      "  warnings.warn(\n",
      "/home/dai/anaconda3/lib/python3.11/site-packages/sklearn/metrics/_classification.py:2922: UserWarning: The y_pred values do not sum to one. Starting from 1.5 thiswill result in an error.\n",
      "  warnings.warn(\n",
      "/home/dai/anaconda3/lib/python3.11/site-packages/sklearn/metrics/_classification.py:2922: UserWarning: The y_pred values do not sum to one. Starting from 1.5 thiswill result in an error.\n",
      "  warnings.warn(\n",
      "/home/dai/anaconda3/lib/python3.11/site-packages/sklearn/metrics/_classification.py:2922: UserWarning: The y_pred values do not sum to one. Starting from 1.5 thiswill result in an error.\n",
      "  warnings.warn(\n",
      "/home/dai/anaconda3/lib/python3.11/site-packages/sklearn/metrics/_classification.py:2922: UserWarning: The y_pred values do not sum to one. Starting from 1.5 thiswill result in an error.\n",
      "  warnings.warn(\n",
      "/home/dai/anaconda3/lib/python3.11/site-packages/sklearn/metrics/_classification.py:2922: UserWarning: The y_pred values do not sum to one. Starting from 1.5 thiswill result in an error.\n",
      "  warnings.warn(\n",
      "/home/dai/anaconda3/lib/python3.11/site-packages/sklearn/metrics/_classification.py:2922: UserWarning: The y_pred values do not sum to one. Starting from 1.5 thiswill result in an error.\n",
      "  warnings.warn(\n",
      "/home/dai/anaconda3/lib/python3.11/site-packages/sklearn/metrics/_classification.py:2922: UserWarning: The y_pred values do not sum to one. Starting from 1.5 thiswill result in an error.\n",
      "  warnings.warn(\n",
      "/home/dai/anaconda3/lib/python3.11/site-packages/sklearn/metrics/_classification.py:2922: UserWarning: The y_pred values do not sum to one. Starting from 1.5 thiswill result in an error.\n",
      "  warnings.warn(\n",
      "/home/dai/anaconda3/lib/python3.11/site-packages/sklearn/metrics/_classification.py:2922: UserWarning: The y_pred values do not sum to one. Starting from 1.5 thiswill result in an error.\n",
      "  warnings.warn(\n",
      "/home/dai/anaconda3/lib/python3.11/site-packages/sklearn/metrics/_classification.py:2922: UserWarning: The y_pred values do not sum to one. Starting from 1.5 thiswill result in an error.\n",
      "  warnings.warn(\n",
      "/home/dai/anaconda3/lib/python3.11/site-packages/sklearn/metrics/_classification.py:2922: UserWarning: The y_pred values do not sum to one. Starting from 1.5 thiswill result in an error.\n",
      "  warnings.warn(\n",
      "/home/dai/anaconda3/lib/python3.11/site-packages/sklearn/metrics/_classification.py:2922: UserWarning: The y_pred values do not sum to one. Starting from 1.5 thiswill result in an error.\n",
      "  warnings.warn(\n",
      "/home/dai/anaconda3/lib/python3.11/site-packages/sklearn/metrics/_classification.py:2922: UserWarning: The y_pred values do not sum to one. Starting from 1.5 thiswill result in an error.\n",
      "  warnings.warn(\n",
      "/home/dai/anaconda3/lib/python3.11/site-packages/sklearn/metrics/_classification.py:2922: UserWarning: The y_pred values do not sum to one. Starting from 1.5 thiswill result in an error.\n",
      "  warnings.warn(\n",
      "/home/dai/anaconda3/lib/python3.11/site-packages/sklearn/metrics/_classification.py:2922: UserWarning: The y_pred values do not sum to one. Starting from 1.5 thiswill result in an error.\n",
      "  warnings.warn(\n",
      "/home/dai/anaconda3/lib/python3.11/site-packages/sklearn/metrics/_classification.py:2922: UserWarning: The y_pred values do not sum to one. Starting from 1.5 thiswill result in an error.\n",
      "  warnings.warn(\n",
      "/home/dai/anaconda3/lib/python3.11/site-packages/sklearn/metrics/_classification.py:2922: UserWarning: The y_pred values do not sum to one. Starting from 1.5 thiswill result in an error.\n",
      "  warnings.warn(\n",
      "/home/dai/anaconda3/lib/python3.11/site-packages/sklearn/metrics/_classification.py:2922: UserWarning: The y_pred values do not sum to one. Starting from 1.5 thiswill result in an error.\n",
      "  warnings.warn(\n",
      "/home/dai/anaconda3/lib/python3.11/site-packages/sklearn/metrics/_classification.py:2922: UserWarning: The y_pred values do not sum to one. Starting from 1.5 thiswill result in an error.\n",
      "  warnings.warn(\n",
      "/home/dai/anaconda3/lib/python3.11/site-packages/sklearn/metrics/_classification.py:2922: UserWarning: The y_pred values do not sum to one. Starting from 1.5 thiswill result in an error.\n",
      "  warnings.warn(\n",
      "/home/dai/anaconda3/lib/python3.11/site-packages/sklearn/metrics/_classification.py:2922: UserWarning: The y_pred values do not sum to one. Starting from 1.5 thiswill result in an error.\n",
      "  warnings.warn(\n",
      "/home/dai/anaconda3/lib/python3.11/site-packages/sklearn/metrics/_classification.py:2922: UserWarning: The y_pred values do not sum to one. Starting from 1.5 thiswill result in an error.\n",
      "  warnings.warn(\n",
      "/home/dai/anaconda3/lib/python3.11/site-packages/sklearn/metrics/_classification.py:2922: UserWarning: The y_pred values do not sum to one. Starting from 1.5 thiswill result in an error.\n",
      "  warnings.warn(\n",
      "/home/dai/anaconda3/lib/python3.11/site-packages/sklearn/metrics/_classification.py:2922: UserWarning: The y_pred values do not sum to one. Starting from 1.5 thiswill result in an error.\n",
      "  warnings.warn(\n",
      "/home/dai/anaconda3/lib/python3.11/site-packages/sklearn/metrics/_classification.py:2922: UserWarning: The y_pred values do not sum to one. Starting from 1.5 thiswill result in an error.\n",
      "  warnings.warn(\n",
      "/home/dai/anaconda3/lib/python3.11/site-packages/sklearn/metrics/_classification.py:2922: UserWarning: The y_pred values do not sum to one. Starting from 1.5 thiswill result in an error.\n",
      "  warnings.warn(\n",
      "/home/dai/anaconda3/lib/python3.11/site-packages/sklearn/metrics/_classification.py:2922: UserWarning: The y_pred values do not sum to one. Starting from 1.5 thiswill result in an error.\n",
      "  warnings.warn(\n",
      "/home/dai/anaconda3/lib/python3.11/site-packages/sklearn/metrics/_classification.py:2922: UserWarning: The y_pred values do not sum to one. Starting from 1.5 thiswill result in an error.\n",
      "  warnings.warn(\n",
      "/home/dai/anaconda3/lib/python3.11/site-packages/sklearn/metrics/_classification.py:2922: UserWarning: The y_pred values do not sum to one. Starting from 1.5 thiswill result in an error.\n",
      "  warnings.warn(\n",
      "/home/dai/anaconda3/lib/python3.11/site-packages/sklearn/metrics/_classification.py:2922: UserWarning: The y_pred values do not sum to one. Starting from 1.5 thiswill result in an error.\n",
      "  warnings.warn(\n",
      "/home/dai/anaconda3/lib/python3.11/site-packages/sklearn/metrics/_classification.py:2922: UserWarning: The y_pred values do not sum to one. Starting from 1.5 thiswill result in an error.\n",
      "  warnings.warn(\n",
      "/home/dai/anaconda3/lib/python3.11/site-packages/sklearn/metrics/_classification.py:2922: UserWarning: The y_pred values do not sum to one. Starting from 1.5 thiswill result in an error.\n",
      "  warnings.warn(\n",
      "/home/dai/anaconda3/lib/python3.11/site-packages/sklearn/metrics/_classification.py:2922: UserWarning: The y_pred values do not sum to one. Starting from 1.5 thiswill result in an error.\n",
      "  warnings.warn(\n",
      "/home/dai/anaconda3/lib/python3.11/site-packages/sklearn/metrics/_classification.py:2922: UserWarning: The y_pred values do not sum to one. Starting from 1.5 thiswill result in an error.\n",
      "  warnings.warn(\n",
      "/home/dai/anaconda3/lib/python3.11/site-packages/sklearn/metrics/_classification.py:2922: UserWarning: The y_pred values do not sum to one. Starting from 1.5 thiswill result in an error.\n",
      "  warnings.warn(\n",
      "/home/dai/anaconda3/lib/python3.11/site-packages/sklearn/metrics/_classification.py:2922: UserWarning: The y_pred values do not sum to one. Starting from 1.5 thiswill result in an error.\n",
      "  warnings.warn(\n",
      "/home/dai/anaconda3/lib/python3.11/site-packages/sklearn/metrics/_classification.py:2922: UserWarning: The y_pred values do not sum to one. Starting from 1.5 thiswill result in an error.\n",
      "  warnings.warn(\n",
      "/home/dai/anaconda3/lib/python3.11/site-packages/sklearn/metrics/_classification.py:2922: UserWarning: The y_pred values do not sum to one. Starting from 1.5 thiswill result in an error.\n",
      "  warnings.warn(\n",
      "/home/dai/anaconda3/lib/python3.11/site-packages/sklearn/metrics/_classification.py:2922: UserWarning: The y_pred values do not sum to one. Starting from 1.5 thiswill result in an error.\n",
      "  warnings.warn(\n",
      "/home/dai/anaconda3/lib/python3.11/site-packages/sklearn/metrics/_classification.py:2922: UserWarning: The y_pred values do not sum to one. Starting from 1.5 thiswill result in an error.\n",
      "  warnings.warn(\n",
      "/home/dai/anaconda3/lib/python3.11/site-packages/sklearn/metrics/_classification.py:2922: UserWarning: The y_pred values do not sum to one. Starting from 1.5 thiswill result in an error.\n",
      "  warnings.warn(\n",
      "/home/dai/anaconda3/lib/python3.11/site-packages/sklearn/metrics/_classification.py:2922: UserWarning: The y_pred values do not sum to one. Starting from 1.5 thiswill result in an error.\n",
      "  warnings.warn(\n",
      "/home/dai/anaconda3/lib/python3.11/site-packages/sklearn/metrics/_classification.py:2922: UserWarning: The y_pred values do not sum to one. Starting from 1.5 thiswill result in an error.\n",
      "  warnings.warn(\n",
      "/home/dai/anaconda3/lib/python3.11/site-packages/sklearn/metrics/_classification.py:2922: UserWarning: The y_pred values do not sum to one. Starting from 1.5 thiswill result in an error.\n",
      "  warnings.warn(\n",
      "/home/dai/anaconda3/lib/python3.11/site-packages/sklearn/metrics/_classification.py:2922: UserWarning: The y_pred values do not sum to one. Starting from 1.5 thiswill result in an error.\n",
      "  warnings.warn(\n",
      "/home/dai/anaconda3/lib/python3.11/site-packages/sklearn/metrics/_classification.py:2922: UserWarning: The y_pred values do not sum to one. Starting from 1.5 thiswill result in an error.\n",
      "  warnings.warn(\n",
      "/home/dai/anaconda3/lib/python3.11/site-packages/sklearn/metrics/_classification.py:2922: UserWarning: The y_pred values do not sum to one. Starting from 1.5 thiswill result in an error.\n",
      "  warnings.warn(\n",
      "/home/dai/anaconda3/lib/python3.11/site-packages/sklearn/metrics/_classification.py:2922: UserWarning: The y_pred values do not sum to one. Starting from 1.5 thiswill result in an error.\n",
      "  warnings.warn(\n",
      "/home/dai/anaconda3/lib/python3.11/site-packages/sklearn/metrics/_classification.py:2922: UserWarning: The y_pred values do not sum to one. Starting from 1.5 thiswill result in an error.\n",
      "  warnings.warn(\n",
      "/home/dai/anaconda3/lib/python3.11/site-packages/sklearn/metrics/_classification.py:2922: UserWarning: The y_pred values do not sum to one. Starting from 1.5 thiswill result in an error.\n",
      "  warnings.warn(\n"
     ]
    },
    {
     "name": "stdout",
     "output_type": "stream",
     "text": [
      "{'var_smoothing': 0.3684210526315789}\n",
      "-1.2441401372989114\n"
     ]
    },
    {
     "name": "stderr",
     "output_type": "stream",
     "text": [
      "/home/dai/anaconda3/lib/python3.11/site-packages/sklearn/metrics/_classification.py:2922: UserWarning: The y_pred values do not sum to one. Starting from 1.5 thiswill result in an error.\n",
      "  warnings.warn(\n",
      "/home/dai/anaconda3/lib/python3.11/site-packages/sklearn/metrics/_classification.py:2922: UserWarning: The y_pred values do not sum to one. Starting from 1.5 thiswill result in an error.\n",
      "  warnings.warn(\n",
      "/home/dai/anaconda3/lib/python3.11/site-packages/sklearn/metrics/_classification.py:2922: UserWarning: The y_pred values do not sum to one. Starting from 1.5 thiswill result in an error.\n",
      "  warnings.warn(\n"
     ]
    }
   ],
   "source": [
    "\n",
    "from sklearn.model_selection import GridSearchCV, StratifiedKFold\n",
    "\n",
    "nb = GaussianNB()\n",
    "kfold=StratifiedKFold(n_splits=5, shuffle=True, random_state=23)\n",
    "\n",
    "var_smoothing = np.linspace(0,1,20)\n",
    "\n",
    "params = {'var_smoothing':var_smoothing}\n",
    "gcv = GridSearchCV(nb,param_grid=params,cv=kfold,scoring='neg_log_loss')\n",
    "gcv.fit(X,y)\n",
    "print(gcv.best_params_)\n",
    "print(gcv.best_score_)\n",
    "df = pd.DataFrame(gcv.cv_results_)"
   ]
  },
  {
   "cell_type": "markdown",
   "metadata": {},
   "source": [
    "LDA"
   ]
  },
  {
   "cell_type": "code",
   "execution_count": 19,
   "metadata": {},
   "outputs": [
    {
     "name": "stdout",
     "output_type": "stream",
     "text": [
      "{'solver': 'svd'}\n",
      "-0.47946220433359044\n"
     ]
    }
   ],
   "source": [
    "from sklearn.discriminant_analysis import LinearDiscriminantAnalysis\n",
    "\n",
    "\n",
    "lda = LinearDiscriminantAnalysis()\n",
    "kfold = StratifiedKFold(n_splits=5, shuffle=True, random_state=23)\n",
    "params = {'solver':['svd', 'lsqr', 'eigen']}\n",
    "gcv = GridSearchCV(lda, param_grid=params, cv=kfold, scoring='neg_log_loss')\n",
    "gcv.fit(X,y)\n",
    "print(gcv.best_params_)\n",
    "print(gcv.best_score_)"
   ]
  },
  {
   "cell_type": "markdown",
   "metadata": {},
   "source": [
    "QDA"
   ]
  },
  {
   "cell_type": "code",
   "execution_count": 20,
   "metadata": {},
   "outputs": [
    {
     "name": "stdout",
     "output_type": "stream",
     "text": [
      "{}\n",
      "-0.4284929344345912\n"
     ]
    }
   ],
   "source": [
    "from sklearn.discriminant_analysis import QuadraticDiscriminantAnalysis\n",
    "\n",
    "\n",
    "qda = QuadraticDiscriminantAnalysis()\n",
    "kfold = StratifiedKFold(n_splits=5, shuffle=True, random_state=23)\n",
    "params = {}\n",
    "gcv = GridSearchCV(qda, param_grid=params, cv=kfold, scoring='neg_log_loss')\n",
    "gcv.fit(X,y)\n",
    "print(gcv.best_params_)\n",
    "print(gcv.best_score_)"
   ]
  }
 ],
 "metadata": {
  "kernelspec": {
   "display_name": "base",
   "language": "python",
   "name": "python3"
  },
  "language_info": {
   "codemirror_mode": {
    "name": "ipython",
    "version": 3
   },
   "file_extension": ".py",
   "mimetype": "text/x-python",
   "name": "python",
   "nbconvert_exporter": "python",
   "pygments_lexer": "ipython3",
   "version": "3.11.5"
  }
 },
 "nbformat": 4,
 "nbformat_minor": 2
}
